Workbook

Sheet Readiness Dashboard
A1: TMK IT Solutions LLP — Franchise Launch Readiness Dashboard
A2: Master 12-Workstream Readiness Tracker | Version 1.0.0 | Updated 2026-10-26
A4: EXECUTIVE READINESS KPIS
A5: Metric Description | B5: Value | C5: Notes & Status Interpretation
A6: Total Program Tasks | B6: =COUNTA('Master Checklist'!A5:A80) | C6: Total itemized deliverables across 12 workstreams
A7: Approved / Verified Tasks | B7: =COUNTIF('Master Checklist'!G5:G80, "Document Approved") + COUNTIF('Master Checklist'!G5:G80, "Process Implemented") + COUNTIF('Master Checklist'!G5:G80, "Process Verified") | C7: Formally verified deliverables meeting acceptance criteria
A8: In Progress / Draft Tasks | B8: =COUNTIF('Master Checklist'!G5:G80, "In Progress") + COUNTIF('Master Checklist'!G5:G80, "Document Created") + COUNTIF('Master Checklist'!G5:G80, "Document Reviewed") | C8: Active work underway across business and engineering units
A9: Not Started Tasks | B9: =COUNTIF('Master Checklist'!G5:G80, "Not Started") | C9: Post-launch or milestone deliverables scheduled for future waves
A10: Active Critical Blockers | B10: =COUNTIFS('Master Checklist'!O5:O80, TRUE, 'Master Checklist'!G5:G80, "<>Document Approved", 'Master Checklist'!G5:G80, "<>Process Verified") | C10: Systemic defects or unvetted contracts that veto gate passage
A11: Launch Readiness Completion % | B11: =ROUND((B6/B5)*100, 1) | C11: Weighted percentage of verified deliverables vs total scope
A13: SIX SEQUENTIAL LAUNCH GATES
A14: Gate ID | B14: Gate Name | C14: Target Date | D14: Current Status | E14: Workstreams Governed
A15: GATE-1 | B15: Gate 1: Business Model Approved | C15: 2026-11-15 | D15: Gate Cleared | E15: Business Model & Commercial Strategy, Finance, Banking & Accounting
A16: GATE-2 | B16: Gate 2: Legal & Financial Readiness | C16: 2026-12-01 | D16: In Progress | E16: Legal, Regulatory & Intellectual Property, Finance, Banking & Accounting
A17: GATE-3 | B17: Gate 3: Product & Delivery Readiness | C17: 2026-12-15 | D17: In Progress | E17: Six-Product Sales Readiness, Central Delivery & Customer Support
A18: GATE-4 | B18: Gate 4: Franchise Recruitment Readiness | C18: 2027-01-05 | D18: In Progress | E18: Franchise Recruitment & Marketing, Partner Onboarding Documents
A19: GATE-5 | B19: Gate 5: Pilot Launch Readiness | C19: 2027-01-20 | D19: Pending | E19: Franchise Operations & SOPs, Franchise Management Technology, Training & Certification, Pilot Launch & Final Approval
A20: GATE-6 | B20: Gate 6: National Expansion Approval | C20: 2027-04-30 | D20: Pending | E20: Governance & Performance Monitoring, Pilot Launch & Final Approval

Sheet Workstream Summary
A1: TMK IT Solutions LLP — 12-Workstream Readiness Summary
A2: Dynamic aggregation of deliverables, completion counts, and readiness percentage by domain
A4: # | B4: Workstream Name | C4: Total Tasks | D4: Approved / Verified | E4: In Progress / Draft | F4: Not Started | G4: Completion %
A5: 1 | B5: Business Model & Commercial Strategy | C5: =COUNTIF('Master Checklist'!$B$5:$B$80, "Business Model & Commercial Strategy") | D5: =COUNTIFS('Master Checklist'!$B$5:$B$80, "Business Model & Commercial Strategy", 'Master Checklist'!$G$5:$G$80, "Document Approved") + COUNTIFS('Master Checklist'!$B$5:$B$80, "Business Model & Commercial Strategy", 'Master Checklist'!$G$5:$G$80, "Process Implemented") + COUNTIFS('Master Checklist'!$B$5:$B$80, "Business Model & Commercial Strategy", 'Master Checklist'!$G$5:$G$80, "Process Verified") | E5: =COUNTIFS('Master Checklist'!$B$5:$B$80, "Business Model & Commercial Strategy", 'Master Checklist'!$G$5:$G$80, "In Progress") + COUNTIFS('Master Checklist'!$B$5:$B$80, "Business Model & Commercial Strategy", 'Master Checklist'!$G$5:$G$80, "Document Created") + COUNTIFS('Master Checklist'!$B$5:$B$80, "Business Model & Commercial Strategy", 'Master Checklist'!$G$5:$G$80, "Document Reviewed") | F5: =COUNTIFS('Master Checklist'!$B$5:$B$80, "Business Model & Commercial Strategy", 'Master Checklist'!$G$5:$G$80, "Not Started") | G5: =IF(C5>0, ROUND((D5/C5)*100, 1), 0)
A6: 2 | B6: Legal, Regulatory & Intellectual Property | C6: =COUNTIF('Master Checklist'!$B$5:$B$80, "Legal, Regulatory & Intellectual Property") | D6: =COUNTIFS('Master Checklist'!$B$5:$B$80, "Legal, Regulatory & Intellectual Property", 'Master Checklist'!$G$5:$G$80, "Document Approved") + COUNTIFS('Master Checklist'!$B$5:$B$80, "Legal, Regulatory & Intellectual Property", 'Master Checklist'!$G$5:$G$80, "Process Implemented") + COUNTIFS('Master Checklist'!$B$5:$B$80, "Legal, Regulatory & Intellectual Property", 'Master Checklist'!$G$5:$G$80, "Process Verified") | E6: =COUNTIFS('Master Checklist'!$B$5:$B$80, "Legal, Regulatory & Intellectual Property", 'Master Checklist'!$G$5:$G$80, "In Progress") + COUNTIFS('Master Checklist'!$B$5:$B$80, "Legal, Regulatory & Intellectual Property", 'Master Checklist'!$G$5:$G$80, "Document Created") + COUNTIFS('Master Checklist'!$B$5:$B$80, "Legal, Regulatory & Intellectual Property", 'Master Checklist'!$G$5:$G$80, "Document Reviewed") | F6: =COUNTIFS('Master Checklist'!$B$5:$B$80, "Legal, Regulatory & Intellectual Property", 'Master Checklist'!$G$5:$G$80, "Not Started") | G6: =IF(C6>0, ROUND((D6/C6)*100, 1), 0)
A7: 3 | B7: Six-Product Sales Readiness | C7: =COUNTIF('Master Checklist'!$B$5:$B$80, "Six-Product Sales Readiness") | D7: =COUNTIFS('Master Checklist'!$B$5:$B$80, "Six-Product Sales Readiness", 'Master Checklist'!$G$5:$G$80, "Document Approved") + COUNTIFS('Master Checklist'!$B$5:$B$80, "Six-Product Sales Readiness", 'Master Checklist'!$G$5:$G$80, "Process Implemented") + COUNTIFS('Master Checklist'!$B$5:$B$80, "Six-Product Sales Readiness", 'Master Checklist'!$G$5:$G$80, "Process Verified") | E7: =COUNTIFS('Master Checklist'!$B$5:$B$80, "Six-Product Sales Readiness", 'Master Checklist'!$G$5:$G$80, "In Progress") + COUNTIFS('Master Checklist'!$B$5:$B$80, "Six-Product Sales Readiness", 'Master Checklist'!$G$5:$G$80, "Document Created") + COUNTIFS('Master Checklist'!$B$5:$B$80, "Six-Product Sales Readiness", 'Master Checklist'!$G$5:$G$80, "Document Reviewed") | F7: =COUNTIFS('Master Checklist'!$B$5:$B$80, "Six-Product Sales Readiness", 'Master Checklist'!$G$5:$G$80, "Not Started") | G7: =IF(C7>0, ROUND((D7/C7)*100, 1), 0)
A8: 4 | B8: Finance, Banking & Accounting | C8: =COUNTIF('Master Checklist'!$B$5:$B$80, "Finance, Banking & Accounting") | D8: =COUNTIFS('Master Checklist'!$B$5:$B$80, "Finance, Banking & Accounting", 'Master Checklist'!$G$5:$G$80, "Document Approved") + COUNTIFS('Master Checklist'!$B$5:$B$80, "Finance, Banking & Accounting", 'Master Checklist'!$G$5:$G$80, "Process Implemented") + COUNTIFS('Master Checklist'!$B$5:$B$80, "Finance, Banking & Accounting", 'Master Checklist'!$G$5:$G$80, "Process Verified") | E8: =COUNTIFS('Master Checklist'!$B$5:$B$80, "Finance, Banking & Accounting", 'Master Checklist'!$G$5:$G$80, "In Progress") + COUNTIFS('Master Checklist'!$B$5:$B$80, "Finance, Banking & Accounting", 'Master Checklist'!$G$5:$G$80, "Document Created") + COUNTIFS('Master Checklist'!$B$5:$B$80, "Finance, Banking & Accounting", 'Master Checklist'!$G$5:$G$80, "Document Reviewed") | F8: =COUNTIFS('Master Checklist'!$B$5:$B$80, "Finance, Banking & Accounting", 'Master Checklist'!$G$5:$G$80, "Not Started") | G8: =IF(C8>0, ROUND((D8/C8)*100, 1), 0)
A9: 5 | B9: Franchise Operations & SOPs | C9: =COUNTIF('Master Checklist'!$B$5:$B$80, "Franchise Operations & SOPs") | D9: =COUNTIFS('Master Checklist'!$B$5:$B$80, "Franchise Operations & SOPs", 'Master Checklist'!$G$5:$G$80, "Document Approved") + COUNTIFS('Master Checklist'!$B$5:$B$80, "Franchise Operations & SOPs", 'Master Checklist'!$G$5:$G$80, "Process Implemented") + COUNTIFS('Master Checklist'!$B$5:$B$80, "Franchise Operations & SOPs", 'Master Checklist'!$G$5:$G$80, "Process Verified") | E9: =COUNTIFS('Master Checklist'!$B$5:$B$80, "Franchise Operations & SOPs", 'Master Checklist'!$G$5:$G$80, "In Progress") + COUNTIFS('Master Checklist'!$B$5:$B$80, "Franchise Operations & SOPs", 'Master Checklist'!$G$5:$G$80, "Document Created") + COUNTIFS('Master Checklist'!$B$5:$B$80, "Franchise Operations & SOPs", 'Master Checklist'!$G$5:$G$80, "Document Reviewed") | F9: =COUNTIFS('Master Checklist'!$B$5:$B$80, "Franchise Operations & SOPs", 'Master Checklist'!$G$5:$G$80, "Not Started") | G9: =IF(C9>0, ROUND((D9/C9)*100, 1), 0)
A10: 6 | B10: Franchise Management Technology | C10: =COUNTIF('Master Checklist'!$B$5:$B$80, "Franchise Management Technology") | D10: =COUNTIFS('Master Checklist'!$B$5:$B$80, "Franchise Management Technology", 'Master Checklist'!$G$5:$G$80, "Document Approved") + COUNTIFS('Master Checklist'!$B$5:$B$80, "Franchise Management Technology", 'Master Checklist'!$G$5:$G$80, "Process Implemented") + COUNTIFS('Master Checklist'!$B$5:$B$80, "Franchise Management Technology", 'Master Checklist'!$G$5:$G$80, "Process Verified") | E10: =COUNTIFS('Master Checklist'!$B$5:$B$80, "Franchise Management Technology", 'Master Checklist'!$G$5:$G$80, "In Progress") + COUNTIFS('Master Checklist'!$B$5:$B$80, "Franchise Management Technology", 'Master Checklist'!$G$5:$G$80, "Document Created") + COUNTIFS('Master Checklist'!$B$5:$B$80, "Franchise Management Technology", 'Master Checklist'!$G$5:$G$80, "Document Reviewed") | F10: =COUNTIFS('Master Checklist'!$B$5:$B$80, "Franchise Management Technology", 'Master Checklist'!$G$5:$G$80, "Not Started") | G10: =IF(C10>0, ROUND((D10/C10)*100, 1), 0)
A11: 7 | B11: Franchise Recruitment & Marketing | C11: =COUNTIF('Master Checklist'!$B$5:$B$80, "Franchise Recruitment & Marketing") | D11: =COUNTIFS('Master Checklist'!$B$5:$B$80, "Franchise Recruitment & Marketing", 'Master Checklist'!$G$5:$G$80, "Document Approved") + COUNTIFS('Master Checklist'!$B$5:$B$80, "Franchise Recruitment & Marketing", 'Master Checklist'!$G$5:$G$80, "Process Implemented") + COUNTIFS('Master Checklist'!$B$5:$B$80, "Franchise Recruitment & Marketing", 'Master Checklist'!$G$5:$G$80, "Process Verified") | E11: =COUNTIFS('Master Checklist'!$B$5:$B$80, "Franchise Recruitment & Marketing", 'Master Checklist'!$G$5:$G$80, "In Progress") + COUNTIFS('Master Checklist'!$B$5:$B$80, "Franchise Recruitment & Marketing", 'Master Checklist'!$G$5:$G$80, "Document Created") + COUNTIFS('Master Checklist'!$B$5:$B$80, "Franchise Recruitment & Marketing", 'Master Checklist'!$G$5:$G$80, "Document Reviewed") | F11: =COUNTIFS('Master Checklist'!$B$5:$B$80, "Franchise Recruitment & Marketing", 'Master Checklist'!$G$5:$G$80, "Not Started") | G11: =IF(C11>0, ROUND((D11/C11)*100, 1), 0)
A12: 8 | B12: Training & Certification | C12: =COUNTIF('Master Checklist'!$B$5:$B$80, "Training & Certification") | D12: =COUNTIFS('Master Checklist'!$B$5:$B$80, "Training & Certification", 'Master Checklist'!$G$5:$G$80, "Document Approved") + COUNTIFS('Master Checklist'!$B$5:$B$80, "Training & Certification", 'Master Checklist'!$G$5:$G$80, "Process Implemented") + COUNTIFS('Master Checklist'!$B$5:$B$80, "Training & Certification", 'Master Checklist'!$G$5:$G$80, "Process Verified") | E12: =COUNTIFS('Master Checklist'!$B$5:$B$80, "Training & Certification", 'Master Checklist'!$G$5:$G$80, "In Progress") + COUNTIFS('Master Checklist'!$B$5:$B$80, "Training & Certification", 'Master Checklist'!$G$5:$G$80, "Document Created") + COUNTIFS('Master Checklist'!$B$5:$B$80, "Training & Certification", 'Master Checklist'!$G$5:$G$80, "Document Reviewed") | F12: =COUNTIFS('Master Checklist'!$B$5:$B$80, "Training & Certification", 'Master Checklist'!$G$5:$G$80, "Not Started") | G12: =IF(C12>0, ROUND((D12/C12)*100, 1), 0)
A13: 9 | B13: Central Delivery & Customer Support | C13: =COUNTIF('Master Checklist'!$B$5:$B$80, "Central Delivery & Customer Support") | D13: =COUNTIFS('Master Checklist'!$B$5:$B$80, "Central Delivery & Customer Support", 'Master Checklist'!$G$5:$G$80, "Document Approved") + COUNTIFS('Master Checklist'!$B$5:$B$80, "Central Delivery & Customer Support", 'Master Checklist'!$G$5:$G$80, "Process Implemented") + COUNTIFS('Master Checklist'!$B$5:$B$80, "Central Delivery & Customer Support", 'Master Checklist'!$G$5:$G$80, "Process Verified") | E13: =COUNTIFS('Master Checklist'!$B$5:$B$80, "Central Delivery & Customer Support", 'Master Checklist'!$G$5:$G$80, "In Progress") + COUNTIFS('Master Checklist'!$B$5:$B$80, "Central Delivery & Customer Support", 'Master Checklist'!$G$5:$G$80, "Document Created") + COUNTIFS('Master Checklist'!$B$5:$B$80, "Central Delivery & Customer Support", 'Master Checklist'!$G$5:$G$80, "Document Reviewed") | F13: =COUNTIFS('Master Checklist'!$B$5:$B$80, "Central Delivery & Customer Support", 'Master Checklist'!$G$5:$G$80, "Not Started") | G13: =IF(C13>0, ROUND((D13/C13)*100, 1), 0)
A14: 10 | B14: Partner Onboarding Documents | C14: =COUNTIF('Master Checklist'!$B$5:$B$80, "Partner Onboarding Documents") | D14: =COUNTIFS('Master Checklist'!$B$5:$B$80, "Partner Onboarding Documents", 'Master Checklist'!$G$5:$G$80, "Document Approved") + COUNTIFS('Master Checklist'!$B$5:$B$80, "Partner Onboarding Documents", 'Master Checklist'!$G$5:$G$80, "Process Implemented") + COUNTIFS('Master Checklist'!$B$5:$B$80, "Partner Onboarding Documents", 'Master Checklist'!$G$5:$G$80, "Process Verified") | E14: =COUNTIFS('Master Checklist'!$B$5:$B$80, "Partner Onboarding Documents", 'Master Checklist'!$G$5:$G$80, "In Progress") + COUNTIFS('Master Checklist'!$B$5:$B$80, "Partner Onboarding Documents", 'Master Checklist'!$G$5:$G$80, "Document Created") + COUNTIFS('Master Checklist'!$B$5:$B$80, "Partner Onboarding Documents", 'Master Checklist'!$G$5:$G$80, "Document Reviewed") | F14: =COUNTIFS('Master Checklist'!$B$5:$B$80, "Partner Onboarding Documents", 'Master Checklist'!$G$5:$G$80, "Not Started") | G14: =IF(C14>0, ROUND((D14/C14)*100, 1), 0)
A15: 11 | B15: Governance & Performance Monitoring | C15: =COUNTIF('Master Checklist'!$B$5:$B$80, "Governance & Performance Monitoring") | D15: =COUNTIFS('Master Checklist'!$B$5:$B$80, "Governance & Performance Monitoring", 'Master Checklist'!$G$5:$G$80, "Document Approved") + COUNTIFS('Master Checklist'!$B$5:$B$80, "Governance & Performance Monitoring", 'Master Checklist'!$G$5:$G$80, "Process Implemented") + COUNTIFS('Master Checklist'!$B$5:$B$80, "Governance & Performance Monitoring", 'Master Checklist'!$G$5:$G$80, "Process Verified") | E15: =COUNTIFS('Master Checklist'!$B$5:$B$80, "Governance & Performance Monitoring", 'Master Checklist'!$G$5:$G$80, "In Progress") + COUNTIFS('Master Checklist'!$B$5:$B$80, "Governance & Performance Monitoring", 'Master Checklist'!$G$5:$G$80, "Document Created") + COUNTIFS('Master Checklist'!$B$5:$B$80, "Governance & Performance Monitoring", 'Master Checklist'!$G$5:$G$80, "Document Reviewed") | F15: =COUNTIFS('Master Checklist'!$B$5:$B$80, "Governance & Performance Monitoring", 'Master Checklist'!$G$5:$G$80, "Not Started") | G15: =IF(C15>0, ROUND((D15/C15)*100, 1), 0)
A16: 12 | B16: Pilot Launch & Final Approval | C16: =COUNTIF('Master Checklist'!$B$5:$B$80, "Pilot Launch & Final Approval") | D16: =COUNTIFS('Master Checklist'!$B$5:$B$80, "Pilot Launch & Final Approval", 'Master Checklist'!$G$5:$G$80, "Document Approved") + COUNTIFS('Master Checklist'!$B$5:$B$80, "Pilot Launch & Final Approval", 'Master Checklist'!$G$5:$G$80, "Process Implemented") + COUNTIFS('Master Checklist'!$B$5:$B$80, "Pilot Launch & Final Approval", 'Master Checklist'!$G$5:$G$80, "Process Verified") | E16: =COUNTIFS('Master Checklist'!$B$5:$B$80, "Pilot Launch & Final Approval", 'Master Checklist'!$G$5:$G$80, "In Progress") + COUNTIFS('Master Checklist'!$B$5:$B$80, "Pilot Launch & Final Approval", 'Master Checklist'!$G$5:$G$80, "Document Created") + COUNTIFS('Master Checklist'!$B$5:$B$80, "Pilot Launch & Final Approval", 'Master Checklist'!$G$5:$G$80, "Document Reviewed") | F16: =COUNTIFS('Master Checklist'!$B$5:$B$80, "Pilot Launch & Final Approval", 'Master Checklist'!$G$5:$G$80, "Not Started") | G16: =IF(C16>0, ROUND((D16/C16)*100, 1), 0)
B17: TOTAL ALL WORKSTREAMS | C17: =SUM(C5:C16) | D17: =SUM(D5:D16) | E17: =SUM(E5:E16) | F17: =SUM(F5:F16) | G17: =IF(C17>0, ROUND((D17/C17)*100, 1), 0)

Sheet Owner Summary
A1: TMK IT Solutions LLP — Accountable Owner Task Summary
A2: Resource allocation and task completion by responsible role
A4: Role / Responsible Owner | B4: Domain Focus | C4: Total Tasks Assigned | D4: Verified / Approved | E4: In Progress / Draft | F4: Overdue / Blocked
A5: Analyst 1 | B5: Business Strategy, Research, Documentation & Collateral | C5: =COUNTIF('Master Checklist'!$F$5:$F$80, "Analyst 1") | D5: =COUNTIFS('Master Checklist'!$F$5:$F$80, "Analyst 1", 'Master Checklist'!$G$5:$G$80, "Document Approved") + COUNTIFS('Master Checklist'!$F$5:$F$80, "Analyst 1", 'Master Checklist'!$G$5:$G$80, "Process Implemented") + COUNTIFS('Master Checklist'!$F$5:$F$80, "Analyst 1", 'Master Checklist'!$G$5:$G$80, "Process Verified") | E5: =COUNTIFS('Master Checklist'!$F$5:$F$80, "Analyst 1", 'Master Checklist'!$G$5:$G$80, "In Progress") + COUNTIFS('Master Checklist'!$F$5:$F$80, "Analyst 1", 'Master Checklist'!$G$5:$G$80, "Document Created") + COUNTIFS('Master Checklist'!$F$5:$F$80, "Analyst 1", 'Master Checklist'!$G$5:$G$80, "Document Reviewed") | F5: =COUNTIFS('Master Checklist'!$F$5:$F$80, "Analyst 1", 'Master Checklist'!$L$5:$L$80, "OVERDUE")
A6: Analyst 2 | B6: Financial Modeling, Analytics, Schemas & Excel Math | C6: =COUNTIF('Master Checklist'!$F$5:$F$80, "Analyst 2") | D6: =COUNTIFS('Master Checklist'!$F$5:$F$80, "Analyst 2", 'Master Checklist'!$G$5:$G$80, "Document Approved") + COUNTIFS('Master Checklist'!$F$5:$F$80, "Analyst 2", 'Master Checklist'!$G$5:$G$80, "Process Implemented") + COUNTIFS('Master Checklist'!$F$5:$F$80, "Analyst 2", 'Master Checklist'!$G$5:$G$80, "Process Verified") | E6: =COUNTIFS('Master Checklist'!$F$5:$F$80, "Analyst 2", 'Master Checklist'!$G$5:$G$80, "In Progress") + COUNTIFS('Master Checklist'!$F$5:$F$80, "Analyst 2", 'Master Checklist'!$G$5:$G$80, "Document Created") + COUNTIFS('Master Checklist'!$F$5:$F$80, "Analyst 2", 'Master Checklist'!$G$5:$G$80, "Document Reviewed") | F6: =COUNTIFS('Master Checklist'!$F$5:$F$80, "Analyst 2", 'Master Checklist'!$L$5:$L$80, "OVERDUE")
A7: Legal Counsel | B7: Franchise Agreements, Trademark Licensing & Regulatory Review | C7: =COUNTIF('Master Checklist'!$F$5:$F$80, "Legal Counsel") | D7: =COUNTIFS('Master Checklist'!$F$5:$F$80, "Legal Counsel", 'Master Checklist'!$G$5:$G$80, "Document Approved") + COUNTIFS('Master Checklist'!$F$5:$F$80, "Legal Counsel", 'Master Checklist'!$G$5:$G$80, "Process Implemented") + COUNTIFS('Master Checklist'!$F$5:$F$80, "Legal Counsel", 'Master Checklist'!$G$5:$G$80, "Process Verified") | E7: =COUNTIFS('Master Checklist'!$F$5:$F$80, "Legal Counsel", 'Master Checklist'!$G$5:$G$80, "In Progress") + COUNTIFS('Master Checklist'!$F$5:$F$80, "Legal Counsel", 'Master Checklist'!$G$5:$G$80, "Document Created") + COUNTIFS('Master Checklist'!$F$5:$F$80, "Legal Counsel", 'Master Checklist'!$G$5:$G$80, "Document Reviewed") | F7: =COUNTIFS('Master Checklist'!$F$5:$F$80, "Legal Counsel", 'Master Checklist'!$L$5:$L$80, "OVERDUE")
A8: Lead Software Architect | B8: 6 Software Demo Sandboxes, Cloud HA, RBAC & Provisioning | C8: =COUNTIF('Master Checklist'!$F$5:$F$80, "Lead Software Architect") | D8: =COUNTIFS('Master Checklist'!$F$5:$F$80, "Lead Software Architect", 'Master Checklist'!$G$5:$G$80, "Document Approved") + COUNTIFS('Master Checklist'!$F$5:$F$80, "Lead Software Architect", 'Master Checklist'!$G$5:$G$80, "Process Implemented") + COUNTIFS('Master Checklist'!$F$5:$F$80, "Lead Software Architect", 'Master Checklist'!$G$5:$G$80, "Process Verified") | E8: =COUNTIFS('Master Checklist'!$F$5:$F$80, "Lead Software Architect", 'Master Checklist'!$G$5:$G$80, "In Progress") + COUNTIFS('Master Checklist'!$F$5:$F$80, "Lead Software Architect", 'Master Checklist'!$G$5:$G$80, "Document Created") + COUNTIFS('Master Checklist'!$F$5:$F$80, "Lead Software Architect", 'Master Checklist'!$G$5:$G$80, "Document Reviewed") | F8: =COUNTIFS('Master Checklist'!$F$5:$F$80, "Lead Software Architect", 'Master Checklist'!$L$5:$L$80, "OVERDUE")
A9: Finance Director / CA | B9: Banking Escrow, GST Pass-Through Tax & Solvency Verification | C9: =COUNTIF('Master Checklist'!$F$5:$F$80, "Finance Director / CA") | D9: =COUNTIFS('Master Checklist'!$F$5:$F$80, "Finance Director / CA", 'Master Checklist'!$G$5:$G$80, "Document Approved") + COUNTIFS('Master Checklist'!$F$5:$F$80, "Finance Director / CA", 'Master Checklist'!$G$5:$G$80, "Process Implemented") + COUNTIFS('Master Checklist'!$F$5:$F$80, "Finance Director / CA", 'Master Checklist'!$G$5:$G$80, "Process Verified") | E9: =COUNTIFS('Master Checklist'!$F$5:$F$80, "Finance Director / CA", 'Master Checklist'!$G$5:$G$80, "In Progress") + COUNTIFS('Master Checklist'!$F$5:$F$80, "Finance Director / CA", 'Master Checklist'!$G$5:$G$80, "Document Created") + COUNTIFS('Master Checklist'!$F$5:$F$80, "Finance Director / CA", 'Master Checklist'!$G$5:$G$80, "Document Reviewed") | F9: =COUNTIFS('Master Checklist'!$F$5:$F$80, "Finance Director / CA", 'Master Checklist'!$L$5:$L$80, "OVERDUE")
A10: Franchise Operations Lead | B10: SOP Handbook, Training Curriculum, Recruitment & Support SLAs | C10: =COUNTIF('Master Checklist'!$F$5:$F$80, "Franchise Operations Lead") | D10: =COUNTIFS('Master Checklist'!$F$5:$F$80, "Franchise Operations Lead", 'Master Checklist'!$G$5:$G$80, "Document Approved") + COUNTIFS('Master Checklist'!$F$5:$F$80, "Franchise Operations Lead", 'Master Checklist'!$G$5:$G$80, "Process Implemented") + COUNTIFS('Master Checklist'!$F$5:$F$80, "Franchise Operations Lead", 'Master Checklist'!$G$5:$G$80, "Process Verified") | E10: =COUNTIFS('Master Checklist'!$F$5:$F$80, "Franchise Operations Lead", 'Master Checklist'!$G$5:$G$80, "In Progress") + COUNTIFS('Master Checklist'!$F$5:$F$80, "Franchise Operations Lead", 'Master Checklist'!$G$5:$G$80, "Document Created") + COUNTIFS('Master Checklist'!$F$5:$F$80, "Franchise Operations Lead", 'Master Checklist'!$G$5:$G$80, "Document Reviewed") | F10: =COUNTIFS('Master Checklist'!$F$5:$F$80, "Franchise Operations Lead", 'Master Checklist'!$L$5:$L$80, "OVERDUE")
A11: Managing Partner | B11: Executive Decisions, Pilot Agreements & Expansion Gate Approvals | C11: =COUNTIF('Master Checklist'!$F$5:$F$80, "Managing Partner") | D11: =COUNTIFS('Master Checklist'!$F$5:$F$80, "Managing Partner", 'Master Checklist'!$G$5:$G$80, "Document Approved") + COUNTIFS('Master Checklist'!$F$5:$F$80, "Managing Partner", 'Master Checklist'!$G$5:$G$80, "Process Implemented") + COUNTIFS('Master Checklist'!$F$5:$F$80, "Managing Partner", 'Master Checklist'!$G$5:$G$80, "Process Verified") | E11: =COUNTIFS('Master Checklist'!$F$5:$F$80, "Managing Partner", 'Master Checklist'!$G$5:$G$80, "In Progress") + COUNTIFS('Master Checklist'!$F$5:$F$80, "Managing Partner", 'Master Checklist'!$G$5:$G$80, "Document Created") + COUNTIFS('Master Checklist'!$F$5:$F$80, "Managing Partner", 'Master Checklist'!$G$5:$G$80, "Document Reviewed") | F11: =COUNTIFS('Master Checklist'!$F$5:$F$80, "Managing Partner", 'Master Checklist'!$L$5:$L$80, "OVERDUE")
A12: TOTAL ALL ROLES | C12: =SUM(C5:C11) | D12: =SUM(D5:D11) | E12: =SUM(E5:E11) | F12: =SUM(F5:F11)

Sheet Master Checklist
A1: TMK IT Solutions LLP — Master 12-Workstream Launch Readiness Checklist
A2: Complete task inventory, ownership RACI, status tracking, launch gating, and blocker registry
A4: Task ID | B4: Workstream | C4: Title | D4: Description | E4: Priority | F4: Owner Role | G4: Status | H4: Classification | I4: Reviewer Role | J4: Approval Authority | K4: Target Date | L4: Overdue Indicator | M4: Dependencies | N4: Launch Gate | O4: Is Blocker? | P4: Related Document
A5: FLR-BMS-001 | B5: Business Model & Commercial Strategy | C5: FOFO Business Model Specification & RACI Architecture | D5: Formulate comprehensive specification of Franchise Owned, Franchise Operated (FOFO) commercial structure, capital division, and operational RACI matrix. | E5: Critical | F5: Analyst 1 | G5: Document Approved | H5: Business research and modeling | I5: Analyst 2 | J5: Managing Partner | K5: 2026-10-26 | L5: =IF(AND(K5<TODAY(), G5<>"Document Approved", G5<>"Process Verified"), "OVERDUE", "On Track") | N5: Gate 1: Business Model Approved | O5: TRUE | P5: clients/tmk-it-solutions/franchise-model/fofo-operating-model.md
A6: FLR-BMS-002 | B6: Business Model & Commercial Strategy | C6: Franchise Fee Structure & Promotional Tier Policy | D6: Establish policy for promotional ₹25,000 joining fee (first 10 units) and standard ₹50,000 fee with documented renewal terms. | E6: High | F6: Analyst 1 | G6: Document Approved | H6: Business research and modeling | I6: Analyst 2 | J6: Managing Partner | K6: 2026-10-26 | L6: =IF(AND(K6<TODAY(), G6<>"Document Approved", G6<>"Process Verified"), "OVERDUE", "On Track") | M6: FLR-BMS-001 | N6: Gate 1: Business Model Approved | O6: FALSE | P6: clients/tmk-it-solutions/franchise-model/fee-structure.md
A7: FLR-BMS-003 | B7: Business Model & Commercial Strategy | C7: 40:60 Net Revenue Sharing Rules & Machine Config | D7: Define contractual revenue-sharing percentages (40% Franchisee : 60% TMK) and machine-readable JSON configuration. | E7: Critical | F7: Analyst 2 | G7: Document Approved | H7: Finance and accounting | I7: Analyst 1 | J7: Finance Director / CA | K7: 2026-10-26 | L7: =IF(AND(K7<TODAY(), G7<>"Document Approved", G7<>"Process Verified"), "OVERDUE", "On Track") | M7: FLR-BMS-001 | N7: Gate 1: Business Model Approved | O7: TRUE | P7: clients/tmk-it-solutions/franchise-model/revenue-sharing-rules.md, clients/tmk-it-solutions/franchise-model/revenue-sharing-config.json
A8: FLR-BMS-004 | B8: Business Model & Commercial Strategy | C8: Six-Product Market Demand Brief & TAM/SAM/SOM Sizing | D8: Quantify total addressable market and serviceable opportunity for TMK software portfolio across Tier-2/3 Indian markets. | E8: High | F8: Analyst 1 | G8: Document Approved | H8: Business research and modeling | I8: Analyst 2 | J8: Practice Lead | K8: 2026-10-26 | L8: =IF(AND(K8<TODAY(), G8<>"Document Approved", G8<>"Process Verified"), "OVERDUE", "On Track") | N8: Gate 1: Business Model Approved | O8: FALSE | P8: clients/tmk-it-solutions/research/six-product-demand-analysis.md
A9: FLR-BMS-005 | B9: Business Model & Commercial Strategy | C9: Taluka-Based Territory Segmentation Strategy | D9: Define territorial boundaries utilizing sub-district (Taluka / Tehsil) administrative divisions with TOS scoring. | E9: High | F9: Analyst 1 | G9: Document Approved | H9: Business research and modeling | I9: Analyst 2 | J9: Practice Lead | K9: 2026-10-26 | L9: =IF(AND(K9<TODAY(), G9<>"Document Approved", G9<>"Process Verified"), "OVERDUE", "On Track") | M9: FLR-BMS-004 | N9: Gate 1: Business Model Approved | O9: FALSE | P9: clients/tmk-it-solutions/research/taluka-based-territory-strategy.md
A10: FLR-BMS-006 | B10: Business Model & Commercial Strategy | C10: Three-Year Expansion Growth Vision & Wave Rollout Plan | D10: Establish 36-month expansion trajectory: Wave 1 Pilot (3 units), Wave 2 Western Maharashtra (15 units), Wave 3 Statewide (50 units). | E10: Medium | F10: Analyst 1 | G10: Document Approved | H10: Documentation and presentation | I10: Managing Partner | J10: Managing Partner | K10: 2026-10-26 | L10: =IF(AND(K10<TODAY(), G10<>"Document Approved", G10<>"Process Verified"), "OVERDUE", "On Track") | M10: FLR-BMS-005 | N10: Gate 1: Business Model Approved | O10: FALSE | P10: clients/tmk-it-solutions/sales-marketing/three-year-growth-vision.md
A11: FLR-LGL-001 | B11: Legal, Regulatory & Intellectual Property | C11: Master Franchise Agreement Drafting | D11: Author complete legal agreement draft specifying license grant, payment terms, territory rules, audit rights, and termination. | E11: Critical | F11: Analyst 1 | G11: Document Created | H11: Documentation and presentation | I11: Legal Counsel | J11: Legal Counsel | K11: 2026-10-26 | L11: =IF(AND(K11<TODAY(), G11<>"Document Approved", G11<>"Process Verified"), "OVERDUE", "On Track") | M11: FLR-BMS-001, FLR-BMS-003 | N11: Gate 2: Legal & Financial Readiness | O11: TRUE | P11: clients/tmk-it-solutions/legal-drafts/franchise-agreement-draft.md
A12: FLR-LGL-002 | B12: Legal, Regulatory & Intellectual Property | C12: Corporate Legal Counsel Review & Compliance Certification | D12: Formal vetting by independent corporate legal counsel under Indian Contract Act, Specific Relief Act, and Consumer Protection laws. | E12: Critical | F12: Legal Counsel | G12: In Progress | H12: Legal and regulatory review | I12: Managing Partner | J12: Legal Counsel | K12: 2026-12-01 | L12: =IF(AND(K12<TODAY(), G12<>"Document Approved", G12<>"Process Verified"), "OVERDUE", "On Track") | M12: FLR-LGL-001 | N12: Gate 2: Legal & Financial Readiness | O12: TRUE | P12: clients/tmk-it-solutions/legal-drafts/franchise-agreement-draft.md
A13: FLR-LGL-003 | B13: Legal, Regulatory & Intellectual Property | C13: Territory Protection Policy & Anti-Encroachment Covenant | D13: Draft formal legal policy governing 90-day Deal Registration Locks, territorial exclusivity boundaries, and dispute arbitration. | E13: High | F13: Analyst 1 | G13: Document Created | H13: Documentation and presentation | I13: Legal Counsel | J13: Legal Counsel | K13: 2026-10-26 | L13: =IF(AND(K13<TODAY(), G13<>"Document Approved", G13<>"Process Verified"), "OVERDUE", "On Track") | M13: FLR-BMS-005 | N13: Gate 2: Legal & Financial Readiness | O13: FALSE | P13: clients/tmk-it-solutions/legal-drafts/territory-policy-draft.md
A14: FLR-LGL-004 | B14: Legal, Regulatory & Intellectual Property | C14: Trademark & Brand Usage License Guidelines | D14: Draft trademark license terms specifying permitted use of TMK IT Solutions logos, trade dress, and signage standards. | E14: High | F14: Analyst 1 | G14: Document Created | H14: Documentation and presentation | I14: Legal Counsel | J14: Legal Counsel | K14: 2026-10-26 | L14: =IF(AND(K14<TODAY(), G14<>"Document Approved", G14<>"Process Verified"), "OVERDUE", "On Track") | N14: Gate 2: Legal & Financial Readiness | O14: FALSE | P14: clients/tmk-it-solutions/legal-drafts/brand-usage-policy-draft.md
A15: FLR-LGL-005 | B15: Legal, Regulatory & Intellectual Property | C15: Franchise Renewal, Buyback & Termination Policies | D15: Formulate legal policies governing contract renewals, performance hurdle benchmarks, voluntary surrender, and default termination. | E15: High | F15: Analyst 1 | G15: Document Created | H15: Documentation and presentation | I15: Legal Counsel | J15: Legal Counsel | K15: 2026-10-26 | L15: =IF(AND(K15<TODAY(), G15<>"Document Approved", G15<>"Process Verified"), "OVERDUE", "On Track") | M15: FLR-LGL-001 | N15: Gate 2: Legal & Financial Readiness | O15: FALSE | P15: clients/tmk-it-solutions/legal-drafts/franchise-renewal-policy-draft.md, clients/tmk-it-solutions/legal-drafts/franchise-termination-policy-draft.md
A16: FLR-LGL-006 | B16: Legal, Regulatory & Intellectual Property | C16: Non-Disclosure & Mutual Confidentiality Agreement | D16: Draft bilateral NDA executed with prospective franchise candidates prior to sharing proprietary product documentation. | E16: Medium | F16: Analyst 1 | G16: Document Created | H16: Documentation and presentation | I16: Legal Counsel | J16: Legal Counsel | K16: 2026-10-26 | L16: =IF(AND(K16<TODAY(), G16<>"Document Approved", G16<>"Process Verified"), "OVERDUE", "On Track") | N16: Gate 2: Legal & Financial Readiness | O16: FALSE | P16: clients/tmk-it-solutions/legal-drafts/confidentiality-agreement-draft.md
A17: FLR-PRD-001 | B17: Six-Product Sales Readiness | C17: Cloud Enterprise ERP Commercial Profile & Spec | D17: Document product feature breakdown, target MSME buyer personas, pricing tiers, and delivery model for prd-01 Enterprise ERP. | E17: High | F17: Analyst 1 | G17: Document Approved | H17: Documentation and presentation | I17: Lead Software Architect | J17: Lead Software Architect | K17: 2026-10-26 | L17: =IF(AND(K17<TODAY(), G17<>"Document Approved", G17<>"Process Verified"), "OVERDUE", "On Track") | N17: Gate 3: Product & Delivery Readiness | O17: FALSE | P17: clients/tmk-it-solutions/products/devops-automation.md
A18: FLR-PRD-002 | B18: Six-Product Sales Readiness | C18: School & College Management ERP Commercial Profile | D18: Document educational software modules (admissions, fee billing, exams) and school demographic targeting. | E18: High | F18: Analyst 1 | G18: Document Approved | H18: Documentation and presentation | I18: Lead Software Architect | J18: Lead Software Architect | K18: 2026-10-26 | L18: =IF(AND(K18<TODAY(), G18<>"Document Approved", G18<>"Process Verified"), "OVERDUE", "On Track") | N18: Gate 3: Product & Delivery Readiness | O18: FALSE | P18: clients/tmk-it-solutions/products/school-college-erp.md
A19: FLR-PRD-003 | B19: Six-Product Sales Readiness | C19: OMR Examination Software Commercial Profile | D19: Document optical mark recognition software pricing, offline scanning hardware compatibility, and school evaluation workflows. | E19: Medium | F19: Analyst 1 | G19: Document Approved | H19: Documentation and presentation | I19: Lead Software Architect | J19: Lead Software Architect | K19: 2026-10-26 | L19: =IF(AND(K19<TODAY(), G19<>"Document Approved", G19<>"Process Verified"), "OVERDUE", "On Track") | N19: Gate 3: Product & Delivery Readiness | O19: FALSE | P19: clients/tmk-it-solutions/products/omr-software.md
A20: FLR-PRD-004 | B20: Six-Product Sales Readiness | C20: Property Management ERP Commercial Profile | D20: Document housing society, commercial real estate, and tenant maintenance billing software modules. | E20: Medium | F20: Analyst 1 | G20: Document Approved | H20: Documentation and presentation | I20: Lead Software Architect | J20: Lead Software Architect | K20: 2026-10-26 | L20: =IF(AND(K20<TODAY(), G20<>"Document Approved", G20<>"Process Verified"), "OVERDUE", "On Track") | N20: Gate 3: Product & Delivery Readiness | O20: FALSE | P20: clients/tmk-it-solutions/products/property-management-erp.md
A21: FLR-PRD-005 | B21: Six-Product Sales Readiness | C21: Invoicing & Billing App (Web + Mobile) Commercial Profile | D21: Document lightweight GST billing application for retail shops and micro-merchants. | E21: High | F21: Analyst 1 | G21: Document Approved | H21: Documentation and presentation | I21: Lead Software Architect | J21: Lead Software Architect | K21: 2026-10-26 | L21: =IF(AND(K21<TODAY(), G21<>"Document Approved", G21<>"Process Verified"), "OVERDUE", "On Track") | N21: Gate 3: Product & Delivery Readiness | O21: FALSE | P21: clients/tmk-it-solutions/products/invoicing-app-web.md
A22: FLR-PRD-006 | B22: Six-Product Sales Readiness | C22: Sales CRM Platform Commercial Profile | D22: Document lead pipeline management, WhatsApp integration, and sales telemetry for regional businesses. | E22: High | F22: Analyst 1 | G22: Document Approved | H22: Documentation and presentation | I22: Lead Software Architect | J22: Lead Software Architect | K22: 2026-10-26 | L22: =IF(AND(K22<TODAY(), G22<>"Document Approved", G22<>"Process Verified"), "OVERDUE", "On Track") | N22: Gate 3: Product & Delivery Readiness | O22: FALSE | P22: clients/tmk-it-solutions/products/sales-crm.md
A23: FLR-PRD-007 | B23: Six-Product Sales Readiness | C23: Live Multi-Tenant Cloud Demonstration Sandbox | D23: Deploy stable cloud demonstration instances for all 6 products pre-populated with synthetic demonstration data. | E23: Critical | F23: Lead Software Architect | G23: In Progress | H23: Product engineering | I23: Managing Partner | J23: Lead Software Architect | K23: 2026-12-15 | L23: =IF(AND(K23<TODAY(), G23<>"Document Approved", G23<>"Process Verified"), "OVERDUE", "On Track") | M23: FLR-PRD-001, FLR-PRD-002, FLR-PRD-003, FLR-PRD-004, FLR-PRD-005, FLR-PRD-006 | N23: Gate 3: Product & Delivery Readiness | O23: TRUE | P23: clients/tmk-it-solutions/products/products-catalog.json
A24: FLR-PRD-008 | B24: Six-Product Sales Readiness | C24: Competitor Benchmarking & Sales Battlecards | D24: Equip partners with competitive comparisons against TallyPrime, Marg ERP, Teachmint, Vyapar, and Zoho. | E24: High | F24: Analyst 1 | G24: Document Approved | H24: Business research and modeling | I24: Analyst 2 | J24: Practice Lead | K24: 2026-10-26 | L24: =IF(AND(K24<TODAY(), G24<>"Document Approved", G24<>"Process Verified"), "OVERDUE", "On Track") | N24: Gate 3: Product & Delivery Readiness | O24: FALSE | P24: clients/tmk-it-solutions/research/competitor-landscape.md
A25: FLR-FIN-001 | B25: Finance, Banking & Accounting | C25: Financial Assumptions Master Config & Schema Compliance | D25: Establish validated assumptions.json governing CapEx, monthly fixed OpEx, fee schedules, tax rates, and scenarios. | E25: Critical | F25: Analyst 2 | G25: Document Approved | H25: Finance and accounting | I25: Finance Director / CA | J25: Finance Director / CA | K25: 2026-10-26 | L25: =IF(AND(K25<TODAY(), G25<>"Document Approved", G25<>"Process Verified"), "OVERDUE", "On Track") | N25: Gate 1: Business Model Approved | O25: TRUE | P25: clients/tmk-it-solutions/financial-models/assumptions.json
A26: FLR-FIN-002 | B26: Finance, Banking & Accounting | C26: Dynamic 10-Sheet Excel Financial Model Generation | D26: Generate dynamic, formula-linked openpyxl Excel financial model with uppercase formulas and zero hardcoded numbers. | E26: Critical | F26: Analyst 2 | G26: Process Implemented | H26: Finance and accounting | I26: Finance Director / CA | J26: Finance Director / CA | K26: 2026-10-26 | L26: =IF(AND(K26<TODAY(), G26<>"Document Approved", G26<>"Process Verified"), "OVERDUE", "On Track") | M26: FLR-FIN-001 | N26: Gate 1: Business Model Approved | O26: TRUE | P26: clients/tmk-it-solutions/financial-models/tmk_it_solutions_franchise_financial_model.xlsx
A27: FLR-FIN-003 | B27: Finance, Banking & Accounting | C27: 36-Month P&L Projections & Break-Even Analysis Summary | D27: Document narrative summary of monthly cash flows, unit break-even requirements (2 contracts/mo), and payback timeline. | E27: High | F27: Analyst 2 | G27: Document Approved | H27: Documentation and presentation | I27: Analyst 1 | J27: Practice Lead | K27: 2026-10-26 | L27: =IF(AND(K27<TODAY(), G27<>"Document Approved", G27<>"Process Verified"), "OVERDUE", "On Track") | M27: FLR-FIN-002 | N27: Gate 1: Business Model Approved | O27: FALSE | P27: clients/tmk-it-solutions/financial-models/financial-projections-summary.md
A28: FLR-FIN-004 | B28: Finance, Banking & Accounting | C28: Statutory Pass-Through Tax Isolation Engine (18% GST) | D28: Verify that all financial models and billing tools isolate 18% GST from gross billing before computing commission splits. | E28: Critical | F28: Analyst 2 | G28: Process Verified | H28: Finance and accounting | I28: Finance Director / CA | J28: Finance Director / CA | K28: 2026-10-26 | L28: =IF(AND(K28<TODAY(), G28<>"Document Approved", G28<>"Process Verified"), "OVERDUE", "On Track") | M28: FLR-FIN-001 | N28: Gate 2: Legal & Financial Readiness | O28: TRUE | P28: tools/financial-modeling/calculator.py
A29: FLR-FIN-005 | B29: Finance, Banking & Accounting | C29: Franchisee Working Capital Reserve Verification Standard | D29: Codify mandatory liquid capital cushion requirement (₹50,000–₹1,00,000 covering 4–6 months overhead) in assumptions. | E29: High | F29: Analyst 2 | G29: Document Approved | H29: Finance and accounting | I29: Finance Director / CA | J29: Finance Director / CA | K29: 2026-10-26 | L29: =IF(AND(K29<TODAY(), G29<>"Document Approved", G29<>"Process Verified"), "OVERDUE", "On Track") | M29: FLR-FIN-001 | N29: Gate 2: Legal & Financial Readiness | O29: TRUE | P29: clients/tmk-it-solutions/research/franchisee-investment-feasibility.md
A30: FLR-FIN-006 | B30: Finance, Banking & Accounting | C30: Dedicated Franchisor Escrow & Commission Settlement Account | D30: Establish dedicated commercial bank account and automated escrow disbursement procedure for partner revenue splits. | E30: Critical | F30: Finance Director / CA | G30: In Progress | H30: Finance and accounting | I30: Managing Partner | J30: Managing Partner | K30: 2026-12-01 | L30: =IF(AND(K30<TODAY(), G30<>"Document Approved", G30<>"Process Verified"), "OVERDUE", "On Track") | M30: FLR-FIN-004 | N30: Gate 2: Legal & Financial Readiness | O30: TRUE | P30: clients/tmk-it-solutions/legal-drafts/revenue-sharing-policy-draft.md
A31: FLR-OPS-001 | B31: Franchise Operations & SOPs | C31: Franchisee Operations Handbook & Facility Launch SOP | D31: Author operational handbook detailing office setup, brand signage, daily opening/closing procedures, and customer onboarding. | E31: High | F31: Analyst 1 | G31: Document Created | H31: Documentation and presentation | I31: Franchise Operations Lead | J31: Franchise Operations Lead | K31: 2026-10-26 | L31: =IF(AND(K31<TODAY(), G31<>"Document Approved", G31<>"Process Verified"), "OVERDUE", "On Track") | N31: Gate 5: Pilot Launch Readiness | O31: FALSE | P31: clients/tmk-it-solutions/operations/franchise-operations-handbook.md
A32: FLR-OPS-002 | B32: Franchise Operations & SOPs | C32: Customer Support SLA & Engineering Escalation Matrix | D32: Establish formal service level agreement defining resolution windows: P1 Critical (< 2h), P2 Major (< 8h), P3 Minor (< 24h). | E32: Critical | F32: Analyst 1 | G32: Document Approved | H32: Franchise operations | I32: Lead Software Architect | J32: Lead Software Architect | K32: 2026-10-26 | L32: =IF(AND(K32<TODAY(), G32<>"Document Approved", G32<>"Process Verified"), "OVERDUE", "On Track") | N32: Gate 3: Product & Delivery Readiness | O32: TRUE | P32: clients/tmk-it-solutions/operations/support-sla-matrix.md
A33: FLR-OPS-003 | B33: Franchise Operations & SOPs | C33: Franchise Unit Physical Onboarding Journey & Milestones | D33: Document sequential 30-day onboarding journey from contract signing to office launch and commercial go-live. | E33: High | F33: Analyst 1 | G33: Document Approved | H33: Franchise operations | I33: Franchise Operations Lead | J33: Franchise Operations Lead | K33: 2026-10-26 | L33: =IF(AND(K33<TODAY(), G33<>"Document Approved", G33<>"Process Verified"), "OVERDUE", "On Track") | M33: FLR-OPS-001 | N33: Gate 5: Pilot Launch Readiness | O33: FALSE | P33: clients/tmk-it-solutions/franchise-model/onboarding-journey.md
A34: FLR-OPS-004 | B34: Franchise Operations & SOPs | C34: Client Onboarding & Data Migration Protocol | D34: Standardize standard operating procedure for migrating customer legacy data (Tally XML, Excel sheets) into TMK Cloud ERP. | E34: Medium | F34: Franchise Operations Lead | G34: In Progress | H34: Franchise operations | I34: Lead Software Architect | J34: Lead Software Architect | K34: 2026-12-15 | L34: =IF(AND(K34<TODAY(), G34<>"Document Approved", G34<>"Process Verified"), "OVERDUE", "On Track") | M34: FLR-PRD-001 | N34: Gate 5: Pilot Launch Readiness | O34: FALSE | P34: clients/tmk-it-solutions/operations/franchise-operations-handbook.md
A35: FLR-OPS-005 | B35: Franchise Operations & SOPs | C35: Franchise Risk Register & Mitigation Playbooks | D35: Maintain exhaustive 5x5 risk scoring matrix covering partner default, regulatory change, and competition risks. | E35: High | F35: Analyst 2 | G35: Document Approved | H35: Management approval | I35: Managing Partner | J35: Managing Partner | K35: 2026-10-26 | L35: =IF(AND(K35<TODAY(), G35<>"Document Approved", G35<>"Process Verified"), "OVERDUE", "On Track") | N35: Gate 5: Pilot Launch Readiness | O35: FALSE | P35: clients/tmk-it-solutions/risks/risk-register.md
A36: FLR-TEC-001 | B36: Franchise Management Technology | C36: Central Partner Portal Architecture & Specification | D36: Specify multi-tenant partner dashboard architecture for commission tracking, lead registration, and support ticketing. | E36: High | F36: Lead Software Architect | G36: Document Created | H36: Technology implementation | I36: Managing Partner | J36: Lead Software Architect | K36: 2026-10-26 | L36: =IF(AND(K36<TODAY(), G36<>"Document Approved", G36<>"Process Verified"), "OVERDUE", "On Track") | N36: Gate 5: Pilot Launch Readiness | O36: FALSE | P36: platform/architecture/system-architecture.md
A37: FLR-TEC-002 | B37: Franchise Management Technology | C37: CRM Lead Protection & 90-Day Deal Registration Engine | D37: Implement automated 90-day prospect locking algorithm in CRM to prevent partner encroachment and channel conflict. | E37: Critical | F37: Lead Software Architect | G37: In Progress | H37: Technology implementation | I37: Franchise Operations Lead | J37: Franchise Operations Lead | K37: 2026-12-20 | L37: =IF(AND(K37<TODAY(), G37<>"Document Approved", G37<>"Process Verified"), "OVERDUE", "On Track") | M37: FLR-TEC-001, FLR-LGL-003 | N37: Gate 5: Pilot Launch Readiness | O37: TRUE | P37: clients/tmk-it-solutions/legal-drafts/territory-policy-draft.md
A38: FLR-TEC-003 | B38: Franchise Management Technology | C38: Automated Software License Key Provisioning Workflow | D38: Automate cloud deployment and cryptographic license key generation upon invoice settlement. | E38: High | F38: Lead Software Architect | G38: In Progress | H38: Product engineering | I38: Finance Director / CA | J38: Lead Software Architect | K38: 2027-01-05 | L38: =IF(AND(K38<TODAY(), G38<>"Document Approved", G38<>"Process Verified"), "OVERDUE", "On Track") | M38: FLR-TEC-001 | N38: Gate 5: Pilot Launch Readiness | O38: FALSE | P38: clients/tmk-it-solutions/products/products-catalog.json
A39: FLR-TEC-004 | B39: Franchise Management Technology | C39: Cloud Infrastructure 99.9% High-Availability Deployment | D39: Deploy resilient containerized Kubernetes / VPS infrastructure with automated daily snapshots and DDoS protection. | E39: High | F39: Lead Software Architect | G39: Process Implemented | H39: Technology implementation | I39: Managing Partner | J39: Lead Software Architect | K39: 2026-10-26 | L39: =IF(AND(K39<TODAY(), G39<>"Document Approved", G39<>"Process Verified"), "OVERDUE", "On Track") | N39: Gate 3: Product & Delivery Readiness | O39: FALSE | P39: clients/tmk-it-solutions/operations/support-sla-matrix.md
A40: FLR-TEC-005 | B40: Franchise Management Technology | C40: Role-Based Access Control (RBAC) & Tenant Security Audit | D40: Enforce strict JWT / OAuth2 authentication ensuring franchisees access only their own territory accounts. | E40: Critical | F40: Lead Software Architect | G40: Process Verified | H40: Technology implementation | I40: Managing Partner | J40: Lead Software Architect | K40: 2026-10-26 | L40: =IF(AND(K40<TODAY(), G40<>"Document Approved", G40<>"Process Verified"), "OVERDUE", "On Track") | M40: FLR-TEC-001 | N40: Gate 5: Pilot Launch Readiness | O40: TRUE | P40: platform/security/security-policy.md
A41: FLR-MKT-001 | B41: Franchise Recruitment & Marketing | C41: Franchise Opportunity Pitch Deck & PPTX Presentation | D41: Build high-impact 10-slide investor presentation detailing business model, unit economics, 6 products, and revenue potential. | E41: Critical | F41: Analyst 1 | G41: Document Approved | H41: Documentation and presentation | I41: Managing Partner | J41: Managing Partner | K41: 2026-10-26 | L41: =IF(AND(K41<TODAY(), G41<>"Document Approved", G41<>"Process Verified"), "OVERDUE", "On Track") | M41: FLR-BMS-001, FLR-FIN-003 | N41: Gate 4: Franchise Recruitment Readiness | O41: TRUE | P41: clients/tmk-it-solutions/presentations/franchise-opportunity-pitch-deck.md, clients/tmk-it-solutions/presentations/franchise-opportunity-pitch-deck.pptx
...

Sheet Gates & Blockers
A1: TMK IT Solutions LLP — Launch Gates & Blocker Specifications
A2: Stage-gate entry/exit criteria, non-negotiable blocker definitions, and override policies
A4: STAGE-GATE GOVERNANCE MATRIX
A5: Gate ID | B5: Gate Name | C5: Target Date | D5: Governing Domains | E5: Mandatory Exit Criteria | F5: Approval Authority
A6: Gate 1 | B6: Gate 1: Business Model Approved | C6: 2026-10-26 | D6: Strategy, Pricing & Revenue Sharing | E6: Break-even units verified (2 contracts/mo); payback <= 12 months; formal sign-off. | F6: Managing Partner
A7: Gate 2 | B7: Gate 2: Legal & Financial Readiness | C7: 2026-12-01 | D7: Legal Agreements, Statutory Taxes & Escrow | E7: Master agreement certified by corporate legal counsel; 18% GST pass-through isolated; bank escrow active. | F7: Corporate Legal Counsel & CA
A8: Gate 3 | B8: Gate 3: Product & Delivery Readiness | C8: 2026-12-15 | D8: 6 Software Products, Central SLAs & Cloud | E8: Live demonstration sandboxes active for all 6 products; support SLA matrix approved; 99.9% cloud HA. | F8: Lead Software Architect
A9: Gate 4 | B9: Gate 4: Franchise Recruitment Readiness | C9: 2027-01-05 | D9: Pitch Collateral, Prospectus & Vetting | E9: Institutional prospectus and FAQ completed with disclaimers; partner application form active; proof-of-funds verified. | F9: Head of Recruitment & Counsel
A10: Gate 5 | B10: Gate 5: Pilot Launch Readiness | C10: 2027-01-20 | D10: Operations SOPs, CRM Deal Lock & Training | E10: 10-day training curriculum completed; 90-day CRM deal lock engine active; 3 pilot partner agreements signed. | F10: Director of Operations & CEO
A11: Gate 6 | B11: Gate 6: National Expansion Approval | C11: 2027-04-30 | D11: Pilot Audits, CSAT & Network Gating | E11: 90-day pilot sales velocity reconciled against model; end-customer CSAT >= 85%; board authorization. | F11: Board of Directors / Executive Lead
A14: CRITICAL LAUNCH BLOCKER TAXONOMY (AUTOMATIC VETO CONDITIONS)
A15: Blocker ID | B15: Affected Gates | C15: Defect Title & Root Cause | D15: Impact & Risk | E15: Mandatory Resolution Requirement | F15: Default Status
A16: BLK-001 | B16: Gate 2, Gate 4 | C16: Unvetted Franchise Contract | D16: Regulatory fines, illegal contract claims, partner litigation | E16: Written certification and legal opinion signed by corporate counsel | F16: Active - In Progress
A17: BLK-002 | B17: Gate 2 | C17: Tax Pass-Through Non-Segregation | D17: Illegal GST tax non-compliance, distorted partner commission calculations | E17: Decimal calculator isolates 18% GST before computing 40:60 splits | F17: Resolved - Verified
A18: BLK-003 | B18: Gate 3 | C18: Unstable Software Demo Sandbox | D18: Failed sales presentations, damaged franchisor credibility, zero conversions | E18: Dedicated cloud demo instances deployed with synthetic test data and 99.9% uptime | F18: Active - Staging
A19: BLK-004 | B19: Gate 3, Gate 5 | C19: Undefined Central SLA Escalation | D19: Unresolved software defects, customer churn, partner dissatisfaction | E19: Published SLA matrix with signed engineering commitment for P1 (< 2h) issues | F19: Resolved - Approved
A20: BLK-005 | B20: Gate 4, Gate 5 | C20: Inadequate Partner Working Capital Reserve | D20: Partner insolvency during initial ramp-up, unit abandonment, brand failure | E20: Mandatory bank statement proof-of-funds verification (minimum ₹50k liquid cushion) | F20: Active - Draft Created
A21: BLK-006 | B21: Gate 6 | C21: Unvalidated Pilot Milestone Audit | D21: Premature national rollout of flawed economic or operational model | E21: Completed 90-day pilot revenue audit and CSAT survey (>= 85%) | F21: Pending - Scheduled
A22: BLK-007 | B22: Gate 5 | C22: Absence of CRM Deal Registration Lock | D22: Partner lead poaching, territory disputes, channel cannibalization | E22: Technical enforcement of 90-day prospect protection in central partner portal | F22: Active - Testing
